Workbook

Sheet Instruction
A3: How to use this e class record
A5: 1 | B5: Complete first the needed Detais in "Input Data Sheet"
A6: 2 | B6: Do not edit colored cells
A7: 3 | B7: Encode the Names of learners alphabetically by Sex
A8: 4 | B8: Encode the scores of learners in appropriate cells based on the componets
A9: 5 | B9: Do not forget to encode the highet possible scosre per item in approiate row in male section only
A10: 6 | B10: The percentage per component will be automaticaly copied from what you encoded in "Input Details Sheet"
A11: 7 | B11: After encoding all needed data go to "Result Sheet" then provide interpretaion and proosed Intervention
A12: 8 | B12: Print the result and submit to your subject coordinator for checking
A13: 9 | B13: From No. 8, submit to your school testing coordinator for verification
A14: 10 | B14: From No. 9, submit to your school head for approval

Sheet Input Details
A1: SCHOOL INFORMATION
A2: Region | C2: XI | G2: Prepared by: | K2: ENGR. PHILIP JAYSON L. LESTOJAS | N2: DepEd Logo | O2: #VALUE!
A3: Division: | C3: Island Garden City of Samal | G3: Designation: | K3: Special Science Teacher I | P3: ←Insert Here your DepEd Logo
A4: School: | C4: Nieves Villarica National High School | G4: Checked: | K4: JUNITH T. REYES
A5: School ID: | C5: 323403 | G5: Designation: | K5: Master Teacher III | N5: Regional Logo | O5: #VALUE!
A6: District: | C6: Babak | G6: Verified: | P6: ←Insert Here your Regional Logo
A7: School Address: | C7: Villarica, Babak, IGaCoS | G7: Designation:
A8: Sch. Contact Number: | G8: Approved: | K8: ELIZABETH A. LACORTE, EdD | N8: Division Logo | O8: #VALUE!
A9: School Email Address | G9: Designation: | K9: Secondary School Principal IV | P9: ←Insert Here your Division Logo
A10: Term | C10: First | G10: ASSESSMENT COMPONENT
A11: School Year: | C11: 2026-2027 | G11: Component | K11: =C12 -> Research 1 | N11: School Logo: | O11: #VALUE!
A12: Subject: | C12: Research 1 | G12: Written/Oral Work | K12: 0.2 | P12: ←Insert Here your School Logo
A13: Grade Level | C13: 12 | G13: Performance Task | K13: 0.5
A14: Section: | C14: TESLA | G14: Summative Test & Term Examination | K14: 0.3
A15: Male | C15: 28 | G15: Note: Refer to the Table below for the percentage per component in every Subject
A16: Female | C16: 32
A17: Total: | C17: =SUM(C15:F16) -> 60
A18: GRADING SYSTEM OF KEY STAGE 2 TO 3
A19: Learning Area | G19: Written/Oral work | I19: Performance Task | K19: Summative Test & Term Examination
A20: English, Filipino, Mathematics, Science , Araling Panlipunan, GMRC/Values Education | G20: 0.2 | I20: 0.5 | K20: 0.3
A21: EPP/TLE, MAPEH | G21: 0.2 | I21: 0.6 | K21: 0.2
A22: GRADING SYSTEM OF KEY STAGE 4
A23: Learning Area | G23: Written/Oral work | I23: Performance Task | K23: Summative Test & Term Examination
A24: SHS Core Subjects, Other SHS Academic Electives | G24: 0.2 | I24: 0.5 | K24: 0.3
A25: SHS Field Exposure, Arts Apprenticeship, Creative production and Innovation | G25: 0.15 | I25: 0.7 | K25: 0.15
A26: SHS, Arts Sports, and Health and wellness Electives | G26: 0.2 | I26: 0.6 | K26: 0.2
A27: SHS Research Electives and Design and Innovation | G27: 0.4 | I27: 0.6
A28: SHS TechPro Electives | G28: 0.15 | I28: 0.65 | K28: 0.2
A29: SHS Work Immersion | G29: 0.2 | I29: 0.8
A31: Instruction:

Sheet E-Class
B3: ='Input Details'!O2 -> #VALUE! | C3: ='Input Details'!O5 -> #VALUE! | D3: ='Input Details'!O8 -> #VALUE! | F3: ='Input Details'!O11 -> #VALUE! | H3: #VALUE! | K3: Region: | N3: ='Input Details'!C2 -> XI | S3: Division: | V3: ='Input Details'!C3 -> Island Garden City of Samal | AB3: School: | AE3: ='Input Details'!C4 -> Nieves Villarica National High School | AJ3: Male: | AL3: ='Input Details'!C15 -> 28
K4: School ID: | N4: ='Input Details'!C5 -> 323403 | S4: District: | V4: ='Input Details'!C6 -> Babak | AB4: Grade & Section: | AE4: ='Input Details'!C13 -> 12 | AF4: ── | AG4: ='Input Details'!C14 -> TESLA | AJ4: Female: | AL4: ='Input Details'!C16 -> 32
K5: Term | N5: ='Input Details'!C10 -> First | S5: School Year:: | V5: ='Input Details'!C11 -> 2026-2027 | AB5: Subject: | AE5: ='Input Details'!C12 -> Research 1 | AJ5: Total: | AL5: =SUM(AL3:AM4) -> 60
A9: MALE | E9: Written / Oral Works | N9: Performance Tasks | W9: Examinations | AK9: Initial Grade | AL9: Final Grade | AM9: Descriptive | AN9: Remarks
W10: Summative Test (60%) | AD10: Term Examination (40%)
A11: No. | B11: Family | C11: First Name | D11: M.I. | E11: 1 | F11: 2 | G11: 3 | H11: 4 | I11: 5 | J11: 6 | K11: T | L11: PS | M11: WS | N11: 1 | O11: 2 | P11: 3 | Q11: 4 | R11: 5 | S11: 6 | T11: T | U11: PS | V11: WS | W11: 1 | X11: 2 | Y11: 3 | Z11: 4 | AA11: T | AB11: PS (ST) | AC11: WS (ST) | AD11: 1 | AE11: 2 | AF11: T | AG11: PS (TE) | AH11: TE | AI11: PS (ST & TE) | AJ11: WS (ST & TE) | BE11: Note: | BF11: Do not Edit Colored Cells
K12: =SUM(E12:J12) -> 0 | L12: 100 | M12: 0.2 | T12: =SUM(N12:S12) -> 0 | U12: 100 | V12: 0.5 | AA12: =SUM(W12:Z12) -> 0 | AB12: 100 | AC12: 0.6 | AF12: =SUM(AD12:AE12) -> 0 | AH12: 0.4 | AJ12: ='Input Details'!K14 -> 0.3
A13: 1 | K13: =SUM(E13:J13) -> 0 | L13: =IFERROR(ROUND(((K13/$K$12)*100),2),"0") -> 0 | M13: =IFERROR(ROUND((L13*$M$12),2),"0") -> 0 | T13: =SUM(N13:S13) -> 0 | U13: =IFERROR(ROUND(((T13/$T$12)*100),2),"0") -> 0 | V13: =IFERROR(ROUND((U13*$V$12),2),"0") -> 0 | AA13: =SUM(W13:Z13) -> 0 | AB13: =IFERROR(ROUND(((AA13/$AA$12)*100),2),"0") -> 0 | AC13: =IFERROR(ROUND((AB13*$AC$12),2),"0") -> 0 | AF13: =SUM(AD13:AE13) -> 0 | AG13: =IFERROR(ROUND(((AF13/$AF$12)*100),2),"0") -> 0 | AH13: =IFERROR(ROUND((AG13*$AH$12),2),"0") -> 0 | AI13: =AC13+AH13 -> 0 | AJ13: =IFERROR(ROUND((AI13*$AJ$12),2),"0") -> 0 | AK13: =M13+V13+AJ13 -> 0 | AL13: =IFERROR(VLOOKUP(AK13,Reference!A4:C11973,2)," ") -> 60 | AM13: =IFERROR(VLOOKUP($AL13,$D$206:$J$307,2),"0") -> Emerging | AN13: =IFERROR(VLOOKUP($AL13,$D$206:$J$307,5),"0") -> Failed | AU13: 1 | AV13: =AF13 -> 0 | AW13: =COUNTBLANK(AD13:AE13) -> 2 | AX13: =VLOOKUP(AW13,$BB$13:$BC$15,2) -> 0 | AY13: =AV13*AX13 -> 0 | AZ13: =VLOOKUP(AW13,$BB$13:$BE$15,3) -> 1000 | BA13: =AV13+AZ13 -> 1000 | BB13: 0 | BC13: 0 | BD13: 0
A14: 2 | K14: =SUM(E14:J14) -> 0 | L14: =IFERROR(ROUND(((K14/$K$12)*100),2),"0") -> 0 | M14: =IFERROR(ROUND((L14*$M$12),2),"0") -> 0 | T14: =SUM(N14:S14) -> 0 | U14: =IFERROR(ROUND(((T14/$T$12)*100),2),"0") -> 0 | V14: =IFERROR(ROUND((U14*$V$12),2),"0") -> 0 | AA14: =SUM(W14:Z14) -> 0 | AB14: =IFERROR(ROUND(((AA14/$AA$12)*100),2),"0") -> 0 | AC14: =IFERROR(ROUND((AB14*$AC$12),2),"0") -> 0 | AF14: =SUM(AD14:AE14) -> 0 | AG14: =IFERROR(ROUND(((AF14/$AF$12)*100),2),"0") -> 0 | AH14: =IFERROR(ROUND((AG14*$AH$12),2),"0") -> 0 | AI14: =AC14+AH14 -> 0 | AJ14: =IFERROR(ROUND((AI14*$AJ$12),2),"0") -> 0 | AK14: =M14+V14+AJ14 -> 0 | AL14: =IFERROR(VLOOKUP(AK14,Reference!A5:C11974,2)," ") | AM14: =IFERROR(VLOOKUP($AL14,$D$206:$J$307,2),"0") -> 0 | AN14: =IFERROR(VLOOKUP($AL14,$D$206:$J$307,5),"0") -> 0 | AU14: 2 | AV14: =AF14 -> 0 | AW14: =COUNTBLANK(AD14:AE14) -> 2 | AX14: =VLOOKUP(AW14,$BB$13:$BC$15,2) -> 0 | AY14: =AV14*AX14 -> 0 | AZ14: =VLOOKUP(AW14,$BB$13:$BE$15,3) -> 1000 | BA14: =AV14+AZ14 -> 1000 | BB14: 1 | BC14: 1 | BD14: 0
A15: 3 | K15: =SUM(E15:J15) -> 0 | L15: =IFERROR(ROUND(((K15/$K$12)*100),2),"0") -> 0 | M15: =IFERROR(ROUND((L15*$M$12),2),"0") -> 0 | T15: =SUM(N15:S15) -> 0 | U15: =IFERROR(ROUND(((T15/$T$12)*100),2),"0") -> 0 | V15: =IFERROR(ROUND((U15*$V$12),2),"0") -> 0 | AA15: =SUM(W15:Z15) -> 0 | AB15: =IFERROR(ROUND(((AA15/$AA$12)*100),2),"0") -> 0 | AC15: =IFERROR(ROUND((AB15*$AC$12),2),"0") -> 0 | AF15: =SUM(AD15:AE15) -> 0 | AG15: =IFERROR(ROUND(((AF15/$AF$12)*100),2),"0") -> 0 | AH15: =IFERROR(ROUND((AG15*$AH$12),2),"0") -> 0 | AI15: =AC15+AH15 -> 0 | AJ15: =IFERROR(ROUND((AI15*$AJ$12),2),"0") -> 0 | AK15: =M15+V15+AJ15 -> 0 | AL15: =IFERROR(VLOOKUP(AK15,Reference!A6:C11975,2)," ") | AM15: =IFERROR(VLOOKUP($AL15,$D$206:$J$307,2),"0") -> 0 | AN15: =IFERROR(VLOOKUP($AL15,$D$206:$J$307,5),"0") -> 0 | AU15: 3 | AV15: =AF15 -> 0 | AW15: =COUNTBLANK(AD15:AE15) -> 2 | AX15: =VLOOKUP(AW15,$BB$13:$BC$15,2) -> 0 | AY15: =AV15*AX15 -> 0 | AZ15: =VLOOKUP(AW15,$BB$13:$BE$15,3) -> 1000 | BA15: =AV15+AZ15 -> 1000 | BB15: 2 | BC15: 0 | BD15: 1000
A16: 4 | K16: =SUM(E16:J16) -> 0 | L16: =IFERROR(ROUND(((K16/$K$12)*100),2),"0") -> 0 | M16: =IFERROR(ROUND((L16*$M$12),2),"0") -> 0 | T16: =SUM(N16:S16) -> 0 | U16: =IFERROR(ROUND(((T16/$T$12)*100),2),"0") -> 0 | V16: =IFERROR(ROUND((U16*$V$12),2),"0") -> 0 | AA16: =SUM(W16:Z16) -> 0 | AB16: =IFERROR(ROUND(((AA16/$AA$12)*100),2),"0") -> 0 | AC16: =IFERROR(ROUND((AB16*$AC$12),2),"0") -> 0 | AF16: =SUM(AD16:AE16) -> 0 | AG16: =IFERROR(ROUND(((AF16/$AF$12)*100),2),"0") -> 0 | AH16: =IFERROR(ROUND((AG16*$AH$12),2),"0") -> 0 | AI16: =AC16+AH16 -> 0 | AJ16: =IFERROR(ROUND((AI16*$AJ$12),2),"0") -> 0 | AK16: =M16+V16+AJ16 -> 0 | AL16: =IFERROR(VLOOKUP(AK16,Reference!A7:C11976,2)," ") | AM16: =IFERROR(VLOOKUP($AL16,$D$206:$J$307,2),"0") -> 0 | AN16: =IFERROR(VLOOKUP($AL16,$D$206:$J$307,5),"0") -> 0 | AU16: 4 | AV16: =AF16 -> 0 | AW16: =COUNTBLANK(AD16:AE16) -> 2 | AX16: =VLOOKUP(AW16,$BB$13:$BC$15,2) -> 0 | AY16: =AV16*AX16 -> 0 | AZ16: =VLOOKUP(AW16,$BB$13:$BE$15,3) -> 1000 | BA16: =AV16+AZ16 -> 1000
A17: 5 | K17: =SUM(E17:J17) -> 0 | L17: =IFERROR(ROUND(((K17/$K$12)*100),2),"0") -> 0 | M17: =IFERROR(ROUND((L17*$M$12),2),"0") -> 0 | T17: =SUM(N17:S17) -> 0 | U17: =IFERROR(ROUND(((T17/$T$12)*100),2),"0") -> 0 | V17: =IFERROR(ROUND((U17*$V$12),2),"0") -> 0 | AA17: =SUM(W17:Z17) -> 0 | AB17: =IFERROR(ROUND(((AA17/$AA$12)*100),2),"0") -> 0 | AC17: =IFERROR(ROUND((AB17*$AC$12),2),"0") -> 0 | AF17: =SUM(AD17:AE17) -> 0 | AG17: =IFERROR(ROUND(((AF17/$AF$12)*100),2),"0") -> 0 | AH17: =IFERROR(ROUND((AG17*$AH$12),2),"0") -> 0 | AI17: =AC17+AH17 -> 0 | AJ17: =IFERROR(ROUND((AI17*$AJ$12),2),"0") -> 0 | AK17: =M17+V17+AJ17 -> 0 | AL17: =IFERROR(VLOOKUP(AK17,Reference!A8:C11977,2)," ") | AM17: =IFERROR(VLOOKUP($AL17,$D$206:$J$307,2),"0") -> 0 | AN17: =IFERROR(VLOOKUP($AL17,$D$206:$J$307,5),"0") -> 0 | AU17: 5 | AV17: =AF17 -> 0 | AW17: =COUNTBLANK(AD17:AE17) -> 2 | AX17: =VLOOKUP(AW17,$BB$13:$BC$15,2) -> 0 | AY17: =AV17*AX17 -> 0 | AZ17: =VLOOKUP(AW17,$BB$13:$BE$15,3) -> 1000 | BA17: =AV17+AZ17 -> 1000
A18: 6 | K18: =SUM(E18:J18) -> 0 | L18: =IFERROR(ROUND(((K18/$K$12)*100),2),"0") -> 0 | M18: =IFERROR(ROUND((L18*$M$12),2),"0") -> 0 | T18: =SUM(N18:S18) -> 0 | U18: =IFERROR(ROUND(((T18/$T$12)*100),2),"0") -> 0 | V18: =IFERROR(ROUND((U18*$V$12),2),"0") -> 0 | AA18: =SUM(W18:Z18) -> 0 | AB18: =IFERROR(ROUND(((AA18/$AA$12)*100),2),"0") -> 0 | AC18: =IFERROR(ROUND((AB18*$AC$12),2),"0") -> 0 | AF18: =SUM(AD18:AE18) -> 0 | AG18: =IFERROR(ROUND(((AF18/$AF$12)*100),2),"0") -> 0 | AH18: =IFERROR(ROUND((AG18*$AH$12),2),"0") -> 0 | AI18: =AC18+AH18 -> 0 | AJ18: =IFERROR(ROUND((AI18*$AJ$12),2),"0") -> 0 | AK18: =M18+V18+AJ18 -> 0 | AL18: =IFERROR(VLOOKUP(AK18,Reference!A9:C11978,2)," ") | AM18: =IFERROR(VLOOKUP($AL18,$D$206:$J$307,2),"0") -> 0 | AN18: =IFERROR(VLOOKUP($AL18,$D$206:$J$307,5),"0") -> 0 | AU18: 6 | AV18: =AF18 -> 0 | AW18: =COUNTBLANK(AD18:AE18) -> 2 | AX18: =VLOOKUP(AW18,$BB$13:$BC$15,2) -> 0 | AY18: =AV18*AX18 -> 0 | AZ18: =VLOOKUP(AW18,$BB$13:$BE$15,3) -> 1000 | BA18: =AV18+AZ18 -> 1000
A19: 7 | K19: =SUM(E19:J19) -> 0 | L19: =IFERROR(ROUND(((K19/$K$12)*100),2),"0") -> 0 | M19: =IFERROR(ROUND((L19*$M$12),2),"0") -> 0 | T19: =SUM(N19:S19) -> 0 | U19: =IFERROR(ROUND(((T19/$T$12)*100),2),"0") -> 0 | V19: =IFERROR(ROUND((U19*$V$12),2),"0") -> 0 | AA19: =SUM(W19:Z19) -> 0 | AB19: =IFERROR(ROUND(((AA19/$AA$12)*100),2),"0") -> 0 | AC19: =IFERROR(ROUND((AB19*$AC$12),2),"0") -> 0 | AF19: =SUM(AD19:AE19) -> 0 | AG19: =IFERROR(ROUND(((AF19/$AF$12)*100),2),"0") -> 0 | AH19: =IFERROR(ROUND((AG19*$AH$12),2),"0") -> 0 | AI19: =AC19+AH19 -> 0 | AJ19: =IFERROR(ROUND((AI19*$AJ$12),2),"0") -> 0 | AK19: =M19+V19+AJ19 -> 0 | AL19: =IFERROR(VLOOKUP(AK19,Reference!A10:C11979,2)," ") | AM19: =IFERROR(VLOOKUP($AL19,$D$206:$J$307,2),"0") -> 0 | AN19: =IFERROR(VLOOKUP($AL19,$D$206:$J$307,5),"0") -> 0 | AU19: 7 | AV19: =AF19 -> 0 | AW19: =COUNTBLANK(AD19:AE19) -> 2 | AX19: =VLOOKUP(AW19,$BB$13:$BC$15,2) -> 0 | AY19: =AV19*AX19 -> 0 | AZ19: =VLOOKUP(AW19,$BB$13:$BE$15,3) -> 1000 | BA19: =AV19+AZ19 -> 1000
A20: 8 | K20: =SUM(E20:J20) -> 0 | L20: =IFERROR(ROUND(((K20/$K$12)*100),2),"0") -> 0 | M20: =IFERROR(ROUND((L20*$M$12),2),"0") -> 0 | T20: =SUM(N20:S20) -> 0 | U20: =IFERROR(ROUND(((T20/$T$12)*100),2),"0") -> 0 | V20: =IFERROR(ROUND((U20*$V$12),2),"0") -> 0 | AA20: =SUM(W20:Z20) -> 0 | AB20: =IFERROR(ROUND(((AA20/$AA$12)*100),2),"0") -> 0 | AC20: =IFERROR(ROUND((AB20*$AC$12),2),"0") -> 0 | AF20: =SUM(AD20:AE20) -> 0 | AG20: =IFERROR(ROUND(((AF20/$AF$12)*100),2),"0") -> 0 | AH20: =IFERROR(ROUND((AG20*$AH$12),2),"0") -> 0 | AI20: =AC20+AH20 -> 0 | AJ20: =IFERROR(ROUND((AI20*$AJ$12),2),"0") -> 0 | AK20: =M20+V20+AJ20 -> 0 | AL20: =IFERROR(VLOOKUP(AK20,Reference!A11:C11980,2)," ") | AM20: =IFERROR(VLOOKUP($AL20,$D$206:$J$307,2),"0") -> 0 | AN20: =IFERROR(VLOOKUP($AL20,$D$206:$J$307,5),"0") -> 0 | AU20: 8 | AV20: =AF20 -> 0 | AW20: =COUNTBLANK(AD20:AE20) -> 2 | AX20: =VLOOKUP(AW20,$BB$13:$BC$15,2) -> 0 | AY20: =AV20*AX20 -> 0 | AZ20: =VLOOKUP(AW20,$BB$13:$BE$15,3) -> 1000 | BA20: =AV20+AZ20 -> 1000
A21: 9 | K21: =SUM(E21:J21) -> 0 | L21: =IFERROR(ROUND(((K21/$K$12)*100),2),"0") -> 0 | M21: =IFERROR(ROUND((L21*$M$12),2),"0") -> 0 | T21: =SUM(N21:S21) -> 0 | U21: =IFERROR(ROUND(((T21/$T$12)*100),2),"0") -> 0 | V21: =IFERROR(ROUND((U21*$V$12),2),"0") -> 0 | AA21: =SUM(W21:Z21) -> 0 | AB21: =IFERROR(ROUND(((AA21/$AA$12)*100),2),"0") -> 0 | AC21: =IFERROR(ROUND((AB21*$AC$12),2),"0") -> 0 | AF21: =SUM(AD21:AE21) -> 0 | AG21: =IFERROR(ROUND(((AF21/$AF$12)*100),2),"0") -> 0 | AH21: =IFERROR(ROUND((AG21*$AH$12),2),"0") -> 0 | AI21: =AC21+AH21 -> 0 | AJ21: =IFERROR(ROUND((AI21*$AJ$12),2),"0") -> 0 | AK21: =M21+V21+AJ21 -> 0 | AL21: =IFERROR(VLOOKUP(AK21,Reference!A12:C11981,2)," ") | AM21: =IFERROR(VLOOKUP($AL21,$D$206:$J$307,2),"0") -> 0 | AN21: =IFERROR(VLOOKUP($AL21,$D$206:$J$307,5),"0") -> 0 | AU21: 9 | AV21: =AF21 -> 0 | AW21: =COUNTBLANK(AD21:AE21) -> 2 | AX21: =VLOOKUP(AW21,$BB$13:$BC$15,2) -> 0 | AY21: =AV21*AX21 -> 0 | AZ21: =VLOOKUP(AW21,$BB$13:$BE$15,3) -> 1000 | BA21: =AV21+AZ21 -> 1000
A22: 10 | K22: =SUM(E22:J22) -> 0 | L22: =IFERROR(ROUND(((K22/$K$12)*100),2),"0") -> 0 | M22: =IFERROR(ROUND((L22*$M$12),2),"0") -> 0 | T22: =SUM(N22:S22) -> 0 | U22: =IFERROR(ROUND(((T22/$T$12)*100),2),"0") -> 0 | V22: =IFERROR(ROUND((U22*$V$12),2),"0") -> 0 | AA22: =SUM(W22:Z22) -> 0 | AB22: =IFERROR(ROUND(((AA22/$AA$12)*100),2),"0") -> 0 | AC22: =IFERROR(ROUND((AB22*$AC$12),2),"0") -> 0 | AF22: =SUM(AD22:AE22) -> 0 | AG22: =IFERROR(ROUND(((AF22/$AF$12)*100),2),"0") -> 0 | AH22: =IFERROR(ROUND((AG22*$AH$12),2),"0") -> 0 | AI22: =AC22+AH22 -> 0 | AJ22: =IFERROR(ROUND((AI22*$AJ$12),2),"0") -> 0 | AK22: =M22+V22+AJ22 -> 0 | AL22: =IFERROR(VLOOKUP(AK22,Reference!A13:C11982,2)," ") | AM22: =IFERROR(VLOOKUP($AL22,$D$206:$J$307,2),"0") -> 0 | AN22: =IFERROR(VLOOKUP($AL22,$D$206:$J$307,5),"0") -> 0 | AU22: 10 | AV22: =AF22 -> 0 | AW22: =COUNTBLANK(AD22:AE22) -> 2 | AX22: =VLOOKUP(AW22,$BB$13:$BC$15,2) -> 0 | AY22: =AV22*AX22 -> 0 | AZ22: =VLOOKUP(AW22,$BB$13:$BE$15,3) -> 1000 | BA22: =AV22+AZ22 -> 1000
A23: 11 | K23: =SUM(E23:J23) -> 0 | L23: =IFERROR(ROUND(((K23/$K$12)*100),2),"0") -> 0 | M23: =IFERROR(ROUND((L23*$M$12),2),"0") -> 0 | T23: =SUM(N23:S23) -> 0 | U23: =IFERROR(ROUND(((T23/$T$12)*100),2),"0") -> 0 | V23: =IFERROR(ROUND((U23*$V$12),2),"0") -> 0 | AA23: =SUM(W23:Z23) -> 0 | AB23: =IFERROR(ROUND(((AA23/$AA$12)*100),2),"0") -> 0 | AC23: =IFERROR(ROUND((AB23*$AC$12),2),"0") -> 0 | AF23: =SUM(AD23:AE23) -> 0 | AG23: =IFERROR(ROUND(((AF23/$AF$12)*100),2),"0") -> 0 | AH23: =IFERROR(ROUND((AG23*$AH$12),2),"0") -> 0 | AI23: =AC23+AH23 -> 0 | AJ23: =IFERROR(ROUND((AI23*$AJ$12),2),"0") -> 0 | AK23: =M23+V23+AJ23 -> 0 | AL23: =IFERROR(VLOOKUP(AK23,Reference!A14:C11983,2)," ") | AM23: =IFERROR(VLOOKUP($AL23,$D$206:$J$307,2),"0") -> 0 | AN23: =IFERROR(VLOOKUP($AL23,$D$206:$J$307,5),"0") -> 0 | AU23: 11 | AV23: =AF23 -> 0 | AW23: =COUNTBLANK(AD23:AE23) -> 2 | AX23: =VLOOKUP(AW23,$BB$13:$BC$15,2) -> 0 | AY23: =AV23*AX23 -> 0 | AZ23: =VLOOKUP(AW23,$BB$13:$BE$15,3) -> 1000 | BA23: =AV23+AZ23 -> 1000
A24: 12 | K24: =SUM(E24:J24) -> 0 | L24: =IFERROR(ROUND(((K24/$K$12)*100),2),"0") -> 0 | M24: =IFERROR(ROUND((L24*$M$12),2),"0") -> 0 | T24: =SUM(N24:S24) -> 0 | U24: =IFERROR(ROUND(((T24/$T$12)*100),2),"0") -> 0 | V24: =IFERROR(ROUND((U24*$V$12),2),"0") -> 0 | AA24: =SUM(W24:Z24) -> 0 | AB24: =IFERROR(ROUND(((AA24/$AA$12)*100),2),"0") -> 0 | AC24: =IFERROR(ROUND((AB24*$AC$12),2),"0") -> 0 | AF24: =SUM(AD24:AE24) -> 0 | AG24: =IFERROR(ROUND(((AF24/$AF$12)*100),2),"0") -> 0 | AH24: =IFERROR(ROUND((AG24*$AH$12),2),"0") -> 0 | AI24: =AC24+AH24 -> 0 | AJ24: =IFERROR(ROUND((AI24*$AJ$12),2),"0") -> 0 | AK24: =M24+V24+AJ24 -> 0 | AL24: =IFERROR(VLOOKUP(AK24,Reference!A15:C11984,2)," ") | AM24: =IFERROR(VLOOKUP($AL24,$D$206:$J$307,2),"0") -> 0 | AN24: =IFERROR(VLOOKUP($AL24,$D$206:$J$307,5),"0") -> 0 | AU24: 12 | AV24: =AF24 -> 0 | AW24: =COUNTBLANK(AD24:AE24) -> 2 | AX24: =VLOOKUP(AW24,$BB$13:$BC$15,2) -> 0 | AY24: =AV24*AX24 -> 0 | AZ24: =VLOOKUP(AW24,$BB$13:$BE$15,3) -> 1000 | BA24: =AV24+AZ24 -> 1000
A25: 13 | K25: =SUM(E25:J25) -> 0 | L25: =IFERROR(ROUND(((K25/$K$12)*100),2),"0") -> 0 | M25: =IFERROR(ROUND((L25*$M$12),2),"0") -> 0 | T25: =SUM(N25:S25) -> 0 | U25: =IFERROR(ROUND(((T25/$T$12)*100),2),"0") -> 0 | V25: =IFERROR(ROUND((U25*$V$12),2),"0") -> 0 | AA25: =SUM(W25:Z25) -> 0 | AB25: =IFERROR(ROUND(((AA25/$AA$12)*100),2),"0") -> 0 | AC25: =IFERROR(ROUND((AB25*$AC$12),2),"0") -> 0 | AF25: =SUM(AD25:AE25) -> 0 | AG25: =IFERROR(ROUND(((AF25/$AF$12)*100),2),"0") -> 0 | AH25: =IFERROR(ROUND((AG25*$AH$12),2),"0") -> 0 | AI25: =AC25+AH25 -> 0 | AJ25: =IFERROR(ROUND((AI25*$AJ$12),2),"0") -> 0 | AK25: =M25+V25+AJ25 -> 0 | AL25: =IFERROR(VLOOKUP(AK25,Reference!A16:C11985,2)," ") | AM25: =IFERROR(VLOOKUP($AL25,$D$206:$J$307,2),"0") -> 0 | AN25: =IFERROR(VLOOKUP($AL25,$D$206:$J$307,5),"0") -> 0 | AU25: 13 | AV25: =AF25 -> 0 | AW25: =COUNTBLANK(AD25:AE25) -> 2 | AX25: =VLOOKUP(AW25,$BB$13:$BC$15,2) -> 0 | AY25: =AV25*AX25 -> 0 | AZ25: =VLOOKUP(AW25,$BB$13:$BE$15,3) -> 1000 | BA25: =AV25+AZ25 -> 1000
A26: 14 | K26: =SUM(E26:J26) -> 0 | L26: =IFERROR(ROUND(((K26/$K$12)*100),2),"0") -> 0 | M26: =IFERROR(ROUND((L26*$M$12),2),"0") -> 0 | T26: =SUM(N26:S26) -> 0 | U26: =IFERROR(ROUND(((T26/$T$12)*100),2),"0") -> 0 | V26: =IFERROR(ROUND((U26*$V$12),2),"0") -> 0 | AA26: =SUM(W26:Z26) -> 0 | AB26: =IFERROR(ROUND(((AA26/$AA$12)*100),2),"0") -> 0 | AC26: =IFERROR(ROUND((AB26*$AC$12),2),"0") -> 0 | AF26: =SUM(AD26:AE26) -> 0 | AG26: =IFERROR(ROUND(((AF26/$AF$12)*100),2),"0") -> 0 | AH26: =IFERROR(ROUND((AG26*$AH$12),2),"0") -> 0 | AI26: =AC26+AH26 -> 0 | AJ26: =IFERROR(ROUND((AI26*$AJ$12),2),"0") -> 0 | AK26: =M26+V26+AJ26 -> 0 | AL26: =IFERROR(VLOOKUP(AK26,Reference!A17:C11986,2)," ") | AM26: =IFERROR(VLOOKUP($AL26,$D$206:$J$307,2),"0") -> 0 | AN26: =IFERROR(VLOOKUP($AL26,$D$206:$J$307,5),"0") -> 0 | AU26: 14 | AV26: =AF26 -> 0 | AW26: =COUNTBLANK(AD26:AE26) -> 2 | AX26: =VLOOKUP(AW26,$BB$13:$BC$15,2) -> 0 | AY26: =AV26*AX26 -> 0 | AZ26: =VLOOKUP(AW26,$BB$13:$BE$15,3) -> 1000 | BA26: =AV26+AZ26 -> 1000
A27: 15 | K27: =SUM(E27:J27) -> 0 | L27: =IFERROR(ROUND(((K27/$K$12)*100),2),"0") -> 0 | M27: =IFERROR(ROUND((L27*$M$12),2),"0") -> 0 | T27: =SUM(N27:S27) -> 0 | U27: =IFERROR(ROUND(((T27/$T$12)*100),2),"0") -> 0 | V27: =IFERROR(ROUND((U27*$V$12),2),"0") -> 0 | AA27: =SUM(W27:Z27) -> 0 | AB27: =IFERROR(ROUND(((AA27/$AA$12)*100),2),"0") -> 0 | AC27: =IFERROR(ROUND((AB27*$AC$12),2),"0") -> 0 | AF27: =SUM(AD27:AE27) -> 0 | AG27: =IFERROR(ROUND(((AF27/$AF$12)*100),2),"0") -> 0 | AH27: =IFERROR(ROUND((AG27*$AH$12),2),"0") -> 0 | AI27: =AC27+AH27 -> 0 | AJ27: =IFERROR(ROUND((AI27*$AJ$12),2),"0") -> 0 | AK27: =M27+V27+AJ27 -> 0 | AL27: =IFERROR(VLOOKUP(AK27,Reference!A18:C11987,2)," ") | AM27: =IFERROR(VLOOKUP($AL27,$D$206:$J$307,2),"0") -> 0 | AN27: =IFERROR(VLOOKUP($AL27,$D$206:$J$307,5),"0") -> 0 | AU27: 15 | AV27: =AF27 -> 0 | AW27: =COUNTBLANK(AD27:AE27) -> 2 | AX27: =VLOOKUP(AW27,$BB$13:$BC$15,2) -> 0 | AY27: =AV27*AX27 -> 0 | AZ27: =VLOOKUP(AW27,$BB$13:$BE$15,3) -> 1000 | BA27: =AV27+AZ27 -> 1000
... A52: 40 | K52: =SUM(E52:J52) -> 0 | L52: =IFERROR(ROUND(((K52/$K$12)*100),2),"0") -> 0 | M52: =IFERROR(ROUND((L52*$M$12),2),"0") -> 0 | T52: =SUM(N52:S52) -> 0 | U52: =IFERROR(ROUND(((T52/$T$12)*100),2),"0") -> 0 | V52: =IFERROR(ROUND((U52*$V$12),2),"0") -> 0 | AA52: =SUM(W52:Z52) -> 0 | AB52: =IFERROR(ROUND(((AA52/$AA$12)*100),2),"0") -> 0 | AC52: =IFERROR(ROUND((AB52*$AC$12),2),"0") -> 0 | AF52: =SUM(AD52:AE52) -> 0 | AG52: =IFERROR(ROUND(((AF52/$AF$12)*100),2),"0") -> 0 | AH52: =IFERROR(ROUND((AG52*$AH$12),2),"0") -> 0 | AI52: =AC52+AH52 -> 0 | AJ52: =IFERROR(ROUND((AI52*$AJ$12),2),"0") -> 0 | AK52: =M52+V52+AJ52 -> 0 | AL52: =IFERROR(VLOOKUP(AK52,Reference!A43:C12012,2)," ") | AM52: =IFERROR(VLOOKUP($AL52,$D$206:$J$307,2),"0") -> 0 | AN52: =IFERROR(VLOOKUP($AL52,$D$206:$J$307,5),"0") -> 0 | AU52: 40 | AV52: =AF52 -> 0 | AW52: =COUNTBLANK(AD52:AE52) -> 2 | AX52: =VLOOKUP(AW52,$BB$13:$BC$15,2) -> 0 | AY52: =AV52*AX52 -> 0 | AZ52: =VLOOKUP(AW52,$BB$13:$BE$15,3) -> 1000 | BA52: =AV52+AZ52 -> 1000
A53: 41 | K53: =SUM(E53:J53) -> 0 | L53: =IFERROR(ROUND(((K53/$K$12)*100),2),"0") -> 0 | M53: =IFERROR(ROUND((L53*$M$12),2),"0") -> 0 | T53: =SUM(N53:S53) -> 0 | U53: =IFERROR(ROUND(((T53/$T$12)*100),2),"0") -> 0 | V53: =IFERROR(ROUND((U53*$V$12),2),"0") -> 0 | AA53: =SUM(W53:Z53) -> 0 | AB53: =IFERROR(ROUND(((AA53/$AA$12)*100),2),"0") -> 0 | AC53: =IFERROR(ROUND((AB53*$AC$12),2),"0") -> 0 | AF53: =SUM(AD53:AE53) -> 0 | AG53: =IFERROR(ROUND(((AF53/$AF$12)*100),2),"0") -> 0 | AH53: =IFERROR(ROUND((AG53*$AH$12),2),"0") -> 0 | AI53: =AC53+AH53 -> 0 | AJ53: =IFERROR(ROUND((AI53*$AJ$12),2),"0") -> 0 | AK53: =M53+V53+AJ53 -> 0 | AL53: =IFERROR(VLOOKUP(AK53,Reference!A52:C12021,2)," ") | AM53: =IFERROR(VLOOKUP($AL53,$D$206:$J$307,2),"0") -> 0 | AN53: =IFERROR(VLOOKUP($AL53,$D$206:$J$307,5),"0") -> 0 | AU53: 41 | AV53: =AF53 -> 0 | AW53: =COUNTBLANK(AD53:AE53) -> 2 | AX53: =VLOOKUP(AW53,$BB$13:$BC$15,2) -> 0 | AY53: =AV53*AX53 -> 0 | AZ53: =VLOOKUP(AW53,$BB$13:$BE$15,3) -> 1000 | BA53: =AV53+AZ53 -> 1000
A54: 42 | K54: =SUM(E54:J54) -> 0 | L54: =IFERROR(ROUND(((K54/$K$12)*100),2),"0") -> 0 | M54: =IFERROR(ROUND((L54*$M$12),2),"0") -> 0 | T54: =SUM(N54:S54) -> 0 | U54: =IFERROR(ROUND(((T54/$T$12)*100),2),"0") -> 0 | V54: =IFERROR(ROUND((U54*$V$12),2),"0") -> 0 | AA54: =SUM(W54:Z54) -> 0 | AB54: =IFERROR(ROUND(((AA54/$AA$12)*100),2),"0") -> 0 | AC54: =IFERROR(ROUND((AB54*$AC$12),2),"0") -> 0 | AF54: =SUM(AD54:AE54) -> 0 | AG54: =IFERROR(ROUND(((AF54/$AF$12)*100),2),"0") -> 0 | AH54: =IFERROR(ROUND((AG54*$AH$12),2),"0") -> 0 | AI54: =AC54+AH54 -> 0 | AJ54: =IFERROR(ROUND((AI54*$AJ$12),2),"0") -> 0 | AK54: =M54+V54+AJ54 -> 0 | AL54: =IFERROR(VLOOKUP(AK54,Reference!A53:C12022,2)," ") | AM54: =IFERROR(VLOOKUP($AL54,$D$206:$J$307,2),"0") -> 0 | AN54: =IFERROR(VLOOKUP($AL54,$D$206:$J$307,5),"0") -> 0 | AU54: 42 | AV54: =AF54 -> 0 | AW54: =COUNTBLANK(AD54:AE54) -> 2 | AX54: =VLOOKUP(AW54,$BB$13:$BC$15,2) -> 0 | AY54: =AV54*AX54 -> 0 | AZ54: =VLOOKUP(AW54,$BB$13:$BE$15,3) -> 1000 | BA54: =AV54+AZ54 -> 1000
A55: 43 | K55: =SUM(E55:J55) -> 0 | L55: =IFERROR(ROUND(((K55/$K$12)*100),2),"0") -> 0 | M55: =IFERROR(ROUND((L55*$M$12),2),"0") -> 0 | T55: =SUM(N55:S55) -> 0 | U55: =IFERROR(ROUND(((T55/$T$12)*100),2),"0") -> 0 | V55: =IFERROR(ROUND((U55*$V$12),2),"0") -> 0 | AA55: =SUM(W55:Z55) -> 0 | AB55: =IFERROR(ROUND(((AA55/$AA$12)*100),2),"0") -> 0 | AC55: =IFERROR(ROUND((AB55*$AC$12),2),"0") -> 0 | AF55: =SUM(AD55:AE55) -> 0 | AG55: =IFERROR(ROUND(((AF55/$AF$12)*100),2),"0") -> 0 | AH55: =IFERROR(ROUND((AG55*$AH$12),2),"0") -> 0 | AI55: =AC55+AH55 -> 0 | AJ55: =IFERROR(ROUND((AI55*$AJ$12),2),"0") -> 0 | AK55: =M55+V55+AJ55 -> 0 | AL55: =IFERROR(VLOOKUP(AK55,Reference!A54:C12023,2)," ") | AM55: =IFERROR(VLOOKUP($AL55,$D$206:$J$307,2),"0") -> 0 | AN55: =IFERROR(VLOOKUP($AL55,$D$206:$J$307,5),"0") -> 0 | AU55: 43 | AV55: =AF55 -> 0 | AW55: =COUNTBLANK(AD55:AE55) -> 2 | AX55: =VLOOKUP(AW55,$BB$13:$BC$15,2) -> 0 | AY55: =AV55*AX55 -> 0 | AZ55: =VLOOKUP(AW55,$BB$13:$BE$15,3) -> 1000 | BA55: =AV55+AZ55 -> 1000
A56: 44 | K56: =SUM(E56:J56) -> 0 | L56: =IFERROR(ROUND(((K56/$K$12)*100),2),"0") -> 0 | M56: =IFERROR(ROUND((L56*$M$12),2),"0") -> 0 | T56: =SUM(N56:S56) -> 0 | U56: =IFERROR(ROUND(((T56/$T$12)*100),2),"0") -> 0 | V56: =IFERROR(ROUND((U56*$V$12),2),"0") -> 0 | AA56: =SUM(W56:Z56) -> 0 | AB56: =IFERROR(ROUND(((AA56/$AA$12)*100),2),"0") -> 0 | AC56: =IFERROR(ROUND((AB56*$AC$12),2),"0") -> 0 | AF56: =SUM(AD56:AE56) -> 0 | AG56: =IFERROR(ROUND(((AF56/$AF$12)*100),2),"0") -> 0 | AH56: =IFERROR(ROUND((AG56*$AH$12),2),"0") -> 0 | AI56: =AC56+AH56 -> 0 | AJ56: =IFERROR(ROUND((AI56*$AJ$12),2),"0") -> 0 | AK56: =M56+V56+AJ56 -> 0 | AL56: =IFERROR(VLOOKUP(AK56,Reference!A55:C12024,2)," ") | AM56: =IFERROR(VLOOKUP($AL56,$D$206:$J$307,2),"0") -> 0 | AN56: =IFERROR(VLOOKUP($AL56,$D$206:$J$307,5),"0") -> 0 | AU56: 44 | AV56: =AF56 -> 0 | AW56: =COUNTBLANK(AD56:AE56) -> 2 | AX56: =VLOOKUP(AW56,$BB$13:$BC$15,2) -> 0 | AY56: =AV56*AX56 -> 0 | AZ56: =VLOOKUP(AW56,$BB$13:$BE$15,3) -> 1000 | BA56: =AV56+AZ56 -> 1000
A57: 45 | K57: =SUM(E57:J57) -> 0 | L57: =IFERROR(ROUND(((K57/$K$12)*100),2),"0") -> 0 | M57: =IFERROR(ROUND((L57*$M$12),2),"0") -> 0 | T57: =SUM(N57:S57) -> 0 | U57: =IFERROR(ROUND(((T57/$T$12)*100),2),"0") -> 0 | V57: =IFERROR(ROUND((U57*$V$12),2),"0") -> 0 | AA57: =SUM(W57:Z57) -> 0 | AB57: =IFERROR(ROUND(((AA57/$AA$12)*100),2),"0") -> 0 | AC57: =IFERROR(ROUND((AB57*$AC$12),2),"0") -> 0 | AF57: =SUM(AD57:AE57) -> 0 | AG57: =IFERROR(ROUND(((AF57/$AF$12)*100),2),"0") -> 0 | AH57: =IFERROR(ROUND((AG57*$AH$12),2),"0") -> 0 | AI57: =AC57+AH57 -> 0 | AJ57: =IFERROR(ROUND((AI57*$AJ$12),2),"0") -> 0 | AK57: =M57+V57+AJ57 -> 0 | AL57: =IFERROR(VLOOKUP(AK57,Reference!A56:C12025,2)," ") | AM57: =IFERROR(VLOOKUP($AL57,$D$206:$J$307,2),"0") -> 0 | AN57: =IFERROR(VLOOKUP($AL57,$D$206:$J$307,5),"0") -> 0 | AU57: 45 | AV57: =AF57 -> 0 | AW57: =COUNTBLANK(AD57:AE57) -> 2 | AX57: =VLOOKUP(AW57,$BB$13:$BC$15,2) -> 0 | AY57: =AV57*AX57 -> 0 | AZ57: =VLOOKUP(AW57,$BB$13:$BE$15,3) -> 1000 | BA57: =AV57+AZ57 -> 1000
A58: 46 | K58: =SUM(E58:J58) -> 0 | L58: =IFERROR(ROUND(((K58/$K$12)*100),2),"0") -> 0 | M58: =IFERROR(ROUND((L58*$M$12),2),"0") -> 0 | T58: =SUM(N58:S58) -> 0 | U58: =IFERROR(ROUND(((T58/$T$12)*100),2),"0") -> 0 | V58: =IFERROR(ROUND((U58*$V$12),2),"0") -> 0 | AA58: =SUM(W58:Z58) -> 0 | AB58: =IFERROR(ROUND(((AA58/$AA$12)*100),2),"0") -> 0 | AC58: =IFERROR(ROUND((AB58*$AC$12),2),"0") -> 0 | AF58: =SUM(AD58:AE58) -> 0 | AG58: =IFERROR(ROUND(((AF58/$AF$12)*100),2),"0") -> 0 | AH58: =IFERROR(ROUND((AG58*$AH$12),2),"0") -> 0 | AI58: =AC58+AH58 -> 0 | AJ58: =IFERROR(ROUND((AI58*$AJ$12),2),"0") -> 0 | AK58: =M58+V58+AJ58 -> 0 | AL58: =IFERROR(VLOOKUP(AK58,Reference!A57:C12026,2)," ") | AM58: =IFERROR(VLOOKUP($AL58,$D$206:$J$307,2),"0") -> 0 | AN58: =IFERROR(VLOOKUP($AL58,$D$206:$J$307,5),"0") -> 0 | AU58: 46 | AV58: =AF58 -> 0 | AW58: =COUNTBLANK(AD58:AE58) -> 2 | AX58: =VLOOKUP(AW58,$BB$13:$BC$15,2) -> 0 | AY58: =AV58*AX58 -> 0 | AZ58: =VLOOKUP(AW58,$BB$13:$BE$15,3) -> 1000 | BA58: =AV58+AZ58 -> 1000
A59: 47 | K59: =SUM(E59:J59) -> 0 | L59: =IFERROR(ROUND(((K59/$K$12)*100),2),"0") -> 0 | M59: =IFERROR(ROUND((L59*$M$12),2),"0") -> 0 | T59: =SUM(N59:S59) -> 0 | U59: =IFERROR(ROUND(((T59/$T$12)*100),2),"0") -> 0 | V59: =IFERROR(ROUND((U59*$V$12),2),"0") -> 0 | AA59: =SUM(W59:Z59) -> 0 | AB59: =IFERROR(ROUND(((AA59/$AA$12)*100),2),"0") -> 0 | AC59: =IFERROR(ROUND((AB59*$AC$12),2),"0") -> 0 | AF59: =SUM(AD59:AE59) -> 0 | AG59: =IFERROR(ROUND(((AF59/$AF$12)*100),2),"0") -> 0 | AH59: =IFERROR(ROUND((AG59*$AH$12),2),"0") -> 0 | AI59: =AC59+AH59 -> 0 | AJ59: =IFERROR(ROUND((AI59*$AJ$12),2),"0") -> 0 | AK59: =M59+V59+AJ59 -> 0 | AL59: =IFERROR(VLOOKUP(AK59,Reference!A58:C12027,2)," ") | AM59: =IFERROR(VLOOKUP($AL59,$D$206:$J$307,2),"0") -> 0 | AN59: =IFERROR(VLOOKUP($AL59,$D$206:$J$307,5),"0") -> 0 | AU59: 47 | AV59: =AF59 -> 0 | AW59: =COUNTBLANK(AD59:AE59) -> 2 | AX59: =VLOOKUP(AW59,$BB$13:$BC$15,2) -> 0 | AY59: =AV59*AX59 -> 0 | AZ59: =VLOOKUP(AW59,$BB$13:$BE$15,3) -> 1000 | BA59: =AV59+AZ59 -> 1000
A60: 48 | K60: =SUM(E60:J60) -> 0 | L60: =IFERROR(ROUND(((K60/$K$12)*100),2),"0") -> 0 | M60: =IFERROR(ROUND((L60*$M$12),2),"0") -> 0 | T60: =SUM(N60:S60) -> 0 | U60: =IFERROR(ROUND(((T60/$T$12)*100),2),"0") -> 0 | V60: =IFERROR(ROUND((U60*$V$12),2),"0") -> 0 | AA60: =SUM(W60:Z60) -> 0 | AB60: =IFERROR(ROUND(((AA60/$AA$12)*100),2),"0") -> 0 | AC60: =IFERROR(ROUND((AB60*$AC$12),2),"0") -> 0 | AF60: =SUM(AD60:AE60) -> 0 | AG60: =IFERROR(ROUND(((AF60/$AF$12)*100),2),"0") -> 0 | AH60: =IFERROR(ROUND((AG60*$AH$12),2),"0") -> 0 | AI60: =AC60+AH60 -> 0 | AJ60: =IFERROR(ROUND((AI60*$AJ$12),2),"0") -> 0 | AK60: =M60+V60+AJ60 -> 0 | AL60: =IFERROR(VLOOKUP(AK60,Reference!A59:C12028,2)," ") | AM60: =IFERROR(VLOOKUP($AL60,$D$206:$J$307,2),"0") -> 0 | AN60: =IFERROR(VLOOKUP($AL60,$D$206:$J$307,5),"0") -> 0 | AU60: 48 | AV60: =AF60 -> 0 | AW60: =COUNTBLANK(AD60:AE60) -> 2 | AX60: =VLOOKUP(AW60,$BB$13:$BC$15,2) -> 0 | AY60: =AV60*AX60 -> 0 | AZ60: =VLOOKUP(AW60,$BB$13:$BE$15,3) -> 1000 | BA60: =AV60+AZ60 -> 1000
A61: 49 | K61: =SUM(E61:J61) -> 0 | L61: =IFERROR(ROUND(((K61/$K$12)*100),2),"0") -> 0 | M61: =IFERROR(ROUND((L61*$M$12),2),"0") -> 0 | T61: =SUM(N61:S61) -> 0 | U61: =IFERROR(ROUND(((T61/$T$12)*100),2),"0") -> 0 | V61: =IFERROR(ROUND((U61*$V$12),2),"0") -> 0 | AA61: =SUM(W61:Z61) -> 0 | AB61: =IFERROR(ROUND(((AA61/$AA$12)*100),2),"0") -> 0 | AC61: =IFERROR(ROUND((AB61*$AC$12),2),"0") -> 0 | AF61: =SUM(AD61:AE61) -> 0 | AG61: =IFERROR(ROUND(((AF61/$AF$12)*100),2),"0") -> 0 | AH61: =IFERROR(ROUND((AG61*$AH$12),2),"0") -> 0 | AI61: =AC61+AH61 -> 0 | AJ61: =IFERROR(ROUND((AI61*$AJ$12),2),"0") -> 0 | AK61: =M61+V61+AJ61 -> 0 | AL61: =IFERROR(VLOOKUP(AK61,Reference!A60:C12029,2)," ") | AM61: =IFERROR(VLOOKUP($AL61,$D$206:$J$307,2),"0") -> 0 | AN61: =IFERROR(VLOOKUP($AL61,$D$206:$J$307,5),"0") -> 0 | AU61: 49 | AV61: =AF61 -> 0 | AW61: =COUNTBLANK(AD61:AE61) -> 2 | AX61: =VLOOKUP(AW61,$BB$13:$BC$15,2) -> 0 | AY61: =AV61*AX61 -> 0 | AZ61: =VLOOKUP(AW61,$BB$13:$BE$15,3) -> 1000 | BA61: =AV61+AZ61 -> 1000
A62: 50 | K62: =SUM(E62:J62) -> 0 | L62: =IFERROR(ROUND(((K62/$K$12)*100),2),"0") -> 0 | M62: =IFERROR(ROUND((L62*$M$12),2),"0") -> 0 | T62: =SUM(N62:S62) -> 0 | U62: =IFERROR(ROUND(((T62/$T$12)*100),2),"0") -> 0 | V62: =IFERROR(ROUND((U62*$V$12),2),"0") -> 0 | AA62: =SUM(W62:Z62) -> 0 | AB62: =IFERROR(ROUND(((AA62/$AA$12)*100),2),"0") -> 0 | AC62: =IFERROR(ROUND((AB62*$AC$12),2),"0") -> 0 | AF62: =SUM(AD62:AE62) -> 0 | AG62: =IFERROR(ROUND(((AF62/$AF$12)*100),2),"0") -> 0 | AH62: =IFERROR(ROUND((AG62*$AH$12),2),"0") -> 0 | AI62: =AC62+AH62 -> 0 | AJ62: =IFERROR(ROUND((AI62*$AJ$12),2),"0") -> 0 | AK62: =M62+V62+AJ62 -> 0 | AL62: =IFERROR(VLOOKUP(AK62,Reference!A61:C12030,2)," ") | AM62: =IFERROR(VLOOKUP($AL62,$D$206:$J$307,2),"0") -> 0 | AN62: =IFERROR(VLOOKUP($AL62,$D$206:$J$307,5),"0") -> 0 | AU62: 50 | AV62: =AF62 -> 0 | AW62: =COUNTBLANK(AD62:AE62) -> 2 | AX62: =VLOOKUP(AW62,$BB$13:$BC$15,2) -> 0 | AY62: =AV62*AX62 -> 0 | AZ62: =VLOOKUP(AW62,$BB$13:$BE$15,3) -> 1000 | BA62: =AV62+AZ62 -> 1000
A63: 51 | K63: =SUM(E63:J63) -> 0 | L63: =IFERROR(ROUND(((K63/$K$12)*100),2),"0") -> 0 | M63: =IFERROR(ROUND((L63*$M$12),2),"0") -> 0 | T63: =SUM(N63:S63) -> 0 | U63: =IFERROR(ROUND(((T63/$T$12)*100),2),"0") -> 0 | V63: =IFERROR(ROUND((U63*$V$12),2),"0") -> 0 | AA63: =SUM(W63:Z63) -> 0 | AB63: =IFERROR(ROUND(((AA63/$AA$12)*100),2),"0") -> 0 | AC63: =IFERROR(ROUND((AB63*$AC$12),2),"0") -> 0 | AF63: =SUM(AD63:AE63) -> 0 | AG63: =IFERROR(ROUND(((AF63/$AF$12)*100),2),"0") -> 0 | AH63: =IFERROR(ROUND((AG63*$AH$12),2),"0") -> 0 | AI63: =AC63+AH63 -> 0 | AJ63: =IFERROR(ROUND((AI63*$AJ$12),2),"0") -> 0 | AK63: =M63+V63+AJ63 -> 0 | AL63: =IFERROR(VLOOKUP(AK63,Reference!A62:C12031,2)," ") | AM63: =IFERROR(VLOOKUP($AL63,$D$206:$J$307,2),"0") -> 0 | AN63: =IFERROR(VLOOKUP($AL63,$D$206:$J$307,5),"0") -> 0 | AU63: 51 | AV63: =AF63 -> 0 | AW63: =COUNTBLANK(AD63:AE63) -> 2 | AX63: =VLOOKUP(AW63,$BB$13:$BC$15,2) -> 0 | AY63: =AV63*AX63 -> 0 | AZ63: =VLOOKUP(AW63,$BB$13:$BE$15,3) -> 1000 | BA63: =AV63+AZ63 -> 1000
A64: 52 | K64: =SUM(E64:J64) -> 0 | L64: =IFERROR(ROUND(((K64/$K$12)*100),2),"0") -> 0 | M64: =IFERROR(ROUND((L64*$M$12),2),"0") -> 0 | T64: =SUM(N64:S64) -> 0 | U64: =IFERROR(ROUND(((T64/$T$12)*100),2),"0") -> 0 | V64: =IFERROR(ROUND((U64*$V$12),2),"0") -> 0 | AA64: =SUM(W64:Z64) -> 0 | AB64: =IFERROR(ROUND(((AA64/$AA$12)*100),2),"0") -> 0 | AC64: =IFERROR(ROUND((AB64*$AC$12),2),"0") -> 0 | AF64: =SUM(AD64:AE64) -> 0 | AG64: =IFERROR(ROUND(((AF64/$AF$12)*100),2),"0") -> 0 | AH64: =IFERROR(ROUND((AG64*$AH$12),2),"0") -> 0 | AI64: =AC64+AH64 -> 0 | AJ64: =IFERROR(ROUND((AI64*$AJ$12),2),"0") -> 0 | AK64: =M64+V64+AJ64 -> 0 | AL64: =IFERROR(VLOOKUP(AK64,Reference!A63:C12032,2)," ") | AM64: =IFERROR(VLOOKUP($AL64,$D$206:$J$307,2),"0") -> 0 | AN64: =IFERROR(VLOOKUP($AL64,$D$206:$J$307,5),"0") -> 0 | AU64: 52 | AV64: =AF64 -> 0 | AW64: =COUNTBLANK(AD64:AE64) -> 2 | AX64: =VLOOKUP(AW64,$BB$13:$BC$15,2) -> 0 | AY64: =AV64*AX64 -> 0 | AZ64: =VLOOKUP(AW64,$BB$13:$BE$15,3) -> 1000 | BA64: =AV64+AZ64 -> 1000
... A92: 80 | K92: =SUM(E92:J92) -> 0 | L92: =IFERROR(ROUND(((K92/$K$12)*100),2),"0") -> 0 | M92: =IFERROR(ROUND((L92*$M$12),2),"0") -> 0 | T92: =SUM(N92:S92) -> 0 | U92: =IFERROR(ROUND(((T92/$T$12)*100),2),"0") -> 0 | V92: =IFERROR(ROUND((U92*$V$12),2),"0") -> 0 | AA92: =SUM(W92:Z92) -> 0 | AB92: =IFERROR(ROUND(((AA92/$AA$12)*100),2),"0") -> 0 | AC92: =IFERROR(ROUND((AB92*$AC$12),2),"0") -> 0 | AF92: =SUM(AD92:AE92) -> 0 | AG92: =IFERROR(ROUND(((AF92/$AF$12)*100),2),"0") -> 0 | AH92: =IFERROR(ROUND((AG92*$AH$12),2),"0") -> 0 | AI92: =AC92+AH92 -> 0 | AJ92: =IFERROR(ROUND((AI92*$AJ$12),2),"0") -> 0 | AK92: =M92+V92+AJ92 -> 0 | AL92: =IFERROR(VLOOKUP(AK92,Reference!A91:C12060,2)," ") | AM92: =IFERROR(VLOOKUP($AL92,$D$206:$J$307,2),"0") -> 0 | AN92: =IFERROR(VLOOKUP($AL92,$D$206:$J$307,5),"0") -> 0 | AU92: 80 | AV92: =AF92 -> 0 | AW92: =COUNTBLANK(AD92:AE92) -> 2 | AX92: =VLOOKUP(AW92,$BB$13:$BC$15,2) -> 0 | AY92: =AV92*AX92 -> 0 | AZ92: =VLOOKUP(AW92,$BB$13:$BE$15,3) -> 1000 | BA92: =AV92+AZ92 -> 1000
A93: Written Work/Oral Work | F93: Performance Task | N93: Summative Test | W93: Term Examination | AE93: Final Grade
A94: Tota HPS | D94: =K12 -> 0 | F94: Tota HPS | L94: =T12 -> 0 | N94: Tota HPS | U94: =AA12 -> 0 | W94: Tota HPS | AC94: =AF12 -> 0 | AE94: Tota HPS | AJ94: 100 | AL94: No. of Emerging | AN94: =AL5-SUM(AN95:AN98) -> 60 | AU94: Max | AV94: =MAX(AV13:AV93) -> 0 | AZ94: Min | BA94: =MIN(BA13:BA93) -> 1000
A95: Number of Learners | D95: =AL5 -> 60 | F95: Number of Learners | L95: =AL5 -> 60 | N95: Number of Learners | U95: =AL5 -> 60 | W95: Number of Learners | AC95: =AL5 -> 60 | AE95: Number of Learners | AJ95: =AL5 -> 60 | AL95: No. of Developing | AN95: =COUNTIF($AL$13:$AL$52,">64")+COUNTIF($AL$53:$AL$92,">64")-AN96-AN97-AN98 -> 0
A96: TTL Scores of Learners | D96: =SUM(K13:K92) -> 0 | F96: TTL Scores of Learners | L96: =SUM(T13:T92) -> 0 | N96: TTL Scores of Learners | U96: =SUM(AA13:AA92) -> 0 | W96: TTL Scores of Learners | AC96: =SUM(AF13:AF92) -> 0 | AE96: TTL Grades of Learners | AJ96: =SUM(AL13:AL92) -> 60 | AL96: No. of Connecting | AN96: =COUNTIF($AL$13:$AL$52,">74")+COUNTIF($AL$53:$AL$92,">74")-AN97-AN98 -> 0
...

Sheet Result
B1: ='Input Details'!O2 -> #VALUE! | D1: ='Input Details'!O5 -> #VALUE! | F1: Republic of the Philippines | Q1: ='Input Details'!O8 -> #VALUE! | S1: ='Input Details'!O11 -> #VALUE!
F2: Department of Education
F3: Region XI
F4: Division of Island Garden City of Samal
B6: REPORT OF LEARNERS PERFORMANCE
B8: School: | D8: ='Input Details'!C4 -> Nieves Villarica National High School | J8: School ID: | L8: ='Input Details'!C5 -> 323403 | N8: District: | P8: ='Input Details'!C6 -> Babak
B9: Grade Level: | D9: ='Input Details'!C13 -> 12 | F9: Section: | H9: ='Input Details'!C14 -> TESLA | K9: Term: | M9: ='Input Details'!C10 -> First | O9: Subject: | Q9: ='Input Details'!C12 -> Research 1
B11: Number of Students: | F11: Male | G11: ='Input Details'!C15 -> 28 | J11: Female: | L11: ='Input Details'!C16 -> 32 | N11: Total: | P11: =G11+L11 -> 60
B13: Table1 | M13: Table2
B14: Written Work and Oral Work | M14: Performance Task
B15: Tota HPS | J15: ='E-Class'!D94 -> 0 | M15: Tota HPS | S15: ='E-Class'!L94 -> 0
B16: TTL Scores of Learners | J16: ='E-Class'!D96 -> 0 | M16: TTL Scores of Learners | S16: ='E-Class'!L96 -> 0
B17: Proficiency | J17: ='E-Class'!D97 -> 0 | M17: Proficiency | S17: ='E-Class'!L97 -> 0
B18: Mean (μ) | J18: ='E-Class'!D98 -> 0 | M18: Mean (μ) | S18: ='E-Class'!L98 -> 0
B19: Number of Learners w/ 75% and Above | J19: ='E-Class'!D99 -> 0 | M19: Number of Learners w/ 75% and Above | S19: ='E-Class'!L99 -> 0
B20: % of Learners w/ 75% and Above | J20: ='E-Class'!D100 -> 0 | M20: % of Learners w/ 75% and Above | S20: ='E-Class'!L100 -> 0
B21: Standard Deviation (σ) | J21: ='E-Class'!D101 -> 0 | M21: Standard Deviation (σ) | S21: ='E-Class'!L101 -> 0
B22: Descriptive: | E22: ='E-Class'!C102 -> #N/A | M22: Descriptive: | P22: ='E-Class'!J102 -> #N/A
B24: Table 3 | M24: Table 4
B25: Summative Test | M25: Term Examination
B26: Tota HPS | J26: ='E-Class'!U94 -> 0 | M26: Tota HPS | S26: ='E-Class'!AC94 -> 0
B27: TTL Scores of Learners | J27: ='E-Class'!U96 -> 0 | M27: TTL Scores of Learners | S27: ='E-Class'!AC96 -> 0
B28: Proficiency | J28: ='E-Class'!U97 -> 0 | M28: Proficiency | S28: ='E-Class'!AC97 -> 0
B29: Mean (μ) | J29: ='E-Class'!U98 -> 0 | M29: Mean (μ) | S29: ='E-Class'!AC98 -> 0
B30: Number of Learners w/ 75% and Above | J30: ='E-Class'!U99 -> 0 | M30: Number of Learners w/ 75% and Above | S30: ='E-Class'!AC99 -> 0
B31: % of Learners w/ 75% and Above | J31: ='E-Class'!U100 -> 0 | M31: % of Learners w/ 75% and Above | S31: ='E-Class'!AC100 -> 0
B32: Standard Deviation (σ) | J32: ='E-Class'!U101 -> 0 | M32: Standard Deviation (σ) | S32: ='E-Class'!AC101 -> 0
B33: Descriptive: | E33: ='E-Class'!T102 -> #N/A | M33: Descriptive: | P33: ='E-Class'!AA102 -> #N/A
B36: Final Grade | O36: SUMMARY
B37: Tota HPS | G37: 100 | I37: No. of Emerging | L37: ='E-Class'!AN94 -> 60 | O37: Component | S37: Proficiency
B38: TTL Grades of Learners | G38: ='E-Class'!AJ96 -> 60 | I38: No. of Developing | L38: ='E-Class'!AN95 -> 0 | O38: Written/Oral Work | S38: =J17 -> 0
B39: Proficiency | G39: ='E-Class'!AJ97 -> 1 | I39: No. of Connecting | L39: ='E-Class'!AN96 -> 0 | O39: Performance Task | S39: =S17 -> 0
B40: Number of Learners w/ 75% and Above | G40: ='E-Class'!AJ98 -> 0 | I40: No. of Benchmarking | L40: ='E-Class'!AN97 -> 0 | O40: Summative Test | S40: =J28 -> 0
B41: % of Learners w/ 75% and Above | G41: ='E-Class'!AJ99 -> 0 | I41: No. of Advancing | L41: ='E-Class'!AN98 -> 0 | O41: Term Examination | S41: =S28 -> 0
B42: % of Failures | G42: ='E-Class'!AJ100 -> 100 | O42: Final Grade | S42: =G39 -> 1
B43: Standard Deviation (σ) | G43: ='E-Class'!AJ101 -> 7.62
B44: Descriptive Analysis: | F44: ='E-Class'!AI102 -> Emerging | I44: Remarks: | K44: ='E-Class'!AN102 -> Failed
C47: =O37 -> Component | D47: =S37 -> Proficiency
C48: =O38 -> Written/Oral Work | D48: =S38 -> 0
C49: =O39 -> Performance Task | D49: =S39 -> 0
...

Sheet Reference
A4: 0 | B4: 60
A5: =A4+0.01 -> 0.01 | B5: 60
A6: =A5+0.01 -> 0.02 | B6: 60
A7: =A6+0.01 -> 0.03 | B7: 60
A8: =A7+0.01 -> 0.04 | B8: 60
A9: =A8+0.01 -> 0.05 | B9: 60
A10: =A9+0.01 -> 0.06 | B10: 60
A11: =A10+0.01 -> 0.07 | B11: 60
A12: =A11+0.01 -> 0.08 | B12: 60
A13: =A12+0.01 -> 0.09 | B13: 60
A14: =A13+0.01 -> 0.1 | B14: 60
A15: =A14+0.01 -> 0.11 | B15: 60
A16: =A15+0.01 -> 0.12 | B16: 60
... A10621: =A10620+0.01 -> 106.17 | B10621: 100
A10622: =A10621+0.01 -> 106.18
A10623: =A10622+0.01 -> 106.19
A10624: =A10623+0.01 -> 106.2
A10625: =A10624+0.01 -> 106.21
A10626: =A10625+0.01 -> 106.22
A10627: =A10626+0.01 -> 106.23
A10628: =A10627+0.01 -> 106.24
A10629: =A10628+0.01 -> 106.25
A10630: =A10629+0.01 -> 106.26
A10631: =A10630+0.01 -> 106.27
A10632: =A10631+0.01 -> 106.28
A10633: =A10632+0.01 -> 106.29
... A15065: =A15064+0.01 -> 150.61
