Workbook

Sheet Setup
A1: RUBRIC SETUP
A3: Subject: | B3: Physics 1 | D3: (shown on every slip as)
A4: Problem Set No.: | B4: 1 | D4: =B3&" • Rubric: Problem Set "&B4
A6: Problem | B6: Type | C6: Final Ans. max | D6: C&E max | E6: Total
A7: 1 | B7: Single-unknown | C7: =IF(B7="Single-unknown",2,4) | D7: =IF(B7="Single-unknown",3,6) | E7: =IF(B7="Single-unknown",5,10)
A8: 2 | B8: Single-unknown | C8: =IF(B8="Single-unknown",2,4) | D8: =IF(B8="Single-unknown",3,6) | E8: =IF(B8="Single-unknown",5,10)
A9: 3 | B9: Single-unknown | C9: =IF(B9="Single-unknown",2,4) | D9: =IF(B9="Single-unknown",3,6) | E9: =IF(B9="Single-unknown",5,10)
A10: 4 | B10: Single-unknown | C10: =IF(B10="Single-unknown",2,4) | D10: =IF(B10="Single-unknown",3,6) | E10: =IF(B10="Single-unknown",5,10)
A11: 5 | B11: Single-unknown | C11: =IF(B11="Single-unknown",2,4) | D11: =IF(B11="Single-unknown",3,6) | E11: =IF(B11="Single-unknown",5,10)
A13: Fill in Subject and Problem Set No. above, set each problem's type, then print the Rubric sheet: it prints 6 identical slips on one A4 page. Cut along the dashed lines. On each slip, circle one number per column for every problem, write the problem score in the Score box, and the sum in the Total box. See the 'Rubric Guide' sheet for what each score means.

Sheet Rubric
A1: =Setup!$B$3&" • Rubric: Problem Set "&Setup!$B$4
A2: Prob | B2: Final Answer | G2: Concept & Execution | N2: Score
A3: 1 | B3: =IF(0<=Setup!$C$7,0,"") | C3: =IF(1<=Setup!$C$7,1,"") | D3: =IF(2<=Setup!$C$7,2,"") | E3: =IF(3<=Setup!$C$7,3,"") | F3: =IF(4<=Setup!$C$7,4,"") | G3: =IF(0<=Setup!$D$7,0,"") | H3: =IF(1<=Setup!$D$7,1,"") | I3: =IF(2<=Setup!$D$7,2,"") | J3: =IF(3<=Setup!$D$7,3,"") | K3: =IF(4<=Setup!$D$7,4,"") | L3: =IF(5<=Setup!$D$7,5,"") | M3: =IF(6<=Setup!$D$7,6,"")
A4: 2 | B4: =IF(0<=Setup!$C$8,0,"") | C4: =IF(1<=Setup!$C$8,1,"") | D4: =IF(2<=Setup!$C$8,2,"") | E4: =IF(3<=Setup!$C$8,3,"") | F4: =IF(4<=Setup!$C$8,4,"") | G4: =IF(0<=Setup!$D$8,0,"") | H4: =IF(1<=Setup!$D$8,1,"") | I4: =IF(2<=Setup!$D$8,2,"") | J4: =IF(3<=Setup!$D$8,3,"") | K4: =IF(4<=Setup!$D$8,4,"") | L4: =IF(5<=Setup!$D$8,5,"") | M4: =IF(6<=Setup!$D$8,6,"")
A5: 3 | B5: =IF(0<=Setup!$C$9,0,"") | C5: =IF(1<=Setup!$C$9,1,"") | D5: =IF(2<=Setup!$C$9,2,"") | E5: =IF(3<=Setup!$C$9,3,"") | F5: =IF(4<=Setup!$C$9,4,"") | G5: =IF(0<=Setup!$D$9,0,"") | H5: =IF(1<=Setup!$D$9,1,"") | I5: =IF(2<=Setup!$D$9,2,"") | J5: =IF(3<=Setup!$D$9,3,"") | K5: =IF(4<=Setup!$D$9,4,"") | L5: =IF(5<=Setup!$D$9,5,"") | M5: =IF(6<=Setup!$D$9,6,"")
A6: 4 | B6: =IF(0<=Setup!$C$10,0,"") | C6: =IF(1<=Setup!$C$10,1,"") | D6: =IF(2<=Setup!$C$10,2,"") | E6: =IF(3<=Setup!$C$10,3,"") | F6: =IF(4<=Setup!$C$10,4,"") | G6: =IF(0<=Setup!$D$10,0,"") | H6: =IF(1<=Setup!$D$10,1,"") | I6: =IF(2<=Setup!$D$10,2,"") | J6: =IF(3<=Setup!$D$10,3,"") | K6: =IF(4<=Setup!$D$10,4,"") | L6: =IF(5<=Setup!$D$10,5,"") | M6: =IF(6<=Setup!$D$10,6,"")
A7: 5 | B7: =IF(0<=Setup!$C$11,0,"") | C7: =IF(1<=Setup!$C$11,1,"") | D7: =IF(2<=Setup!$C$11,2,"") | E7: =IF(3<=Setup!$C$11,3,"") | F7: =IF(4<=Setup!$C$11,4,"") | G7: =IF(0<=Setup!$D$11,0,"") | H7: =IF(1<=Setup!$D$11,1,"") | I7: =IF(2<=Setup!$D$11,2,"") | J7: =IF(3<=Setup!$D$11,3,"") | K7: =IF(4<=Setup!$D$11,4,"") | L7: =IF(5<=Setup!$D$11,5,"") | M7: =IF(6<=Setup!$D$11,6,"")
A8: TOTAL SCORE →
A10: =Setup!$B$3&" • Rubric: Problem Set "&Setup!$B$4
A11: Prob | B11: Final Answer | G11: Concept & Execution | N11: Score
A12: 1 | B12: =IF(0<=Setup!$C$7,0,"") | C12: =IF(1<=Setup!$C$7,1,"") | D12: =IF(2<=Setup!$C$7,2,"") | E12: =IF(3<=Setup!$C$7,3,"") | F12: =IF(4<=Setup!$C$7,4,"") | G12: =IF(0<=Setup!$D$7,0,"") | H12: =IF(1<=Setup!$D$7,1,"") | I12: =IF(2<=Setup!$D$7,2,"") | J12: =IF(3<=Setup!$D$7,3,"") | K12: =IF(4<=Setup!$D$7,4,"") | L12: =IF(5<=Setup!$D$7,5,"") | M12: =IF(6<=Setup!$D$7,6,"")
A13: 2 | B13: =IF(0<=Setup!$C$8,0,"") | C13: =IF(1<=Setup!$C$8,1,"") | D13: =IF(2<=Setup!$C$8,2,"") | E13: =IF(3<=Setup!$C$8,3,"") | F13: =IF(4<=Setup!$C$8,4,"") | G13: =IF(0<=Setup!$D$8,0,"") | H13: =IF(1<=Setup!$D$8,1,"") | I13: =IF(2<=Setup!$D$8,2,"") | J13: =IF(3<=Setup!$D$8,3,"") | K13: =IF(4<=Setup!$D$8,4,"") | L13: =IF(5<=Setup!$D$8,5,"") | M13: =IF(6<=Setup!$D$8,6,"")
A14: 3 | B14: =IF(0<=Setup!$C$9,0,"") | C14: =IF(1<=Setup!$C$9,1,"") | D14: =IF(2<=Setup!$C$9,2,"") | E14: =IF(3<=Setup!$C$9,3,"") | F14: =IF(4<=Setup!$C$9,4,"") | G14: =IF(0<=Setup!$D$9,0,"") | H14: =IF(1<=Setup!$D$9,1,"") | I14: =IF(2<=Setup!$D$9,2,"") | J14: =IF(3<=Setup!$D$9,3,"") | K14: =IF(4<=Setup!$D$9,4,"") | L14: =IF(5<=Setup!$D$9,5,"") | M14: =IF(6<=Setup!$D$9,6,"")
A15: 4 | B15: =IF(0<=Setup!$C$10,0,"") | C15: =IF(1<=Setup!$C$10,1,"") | D15: =IF(2<=Setup!$C$10,2,"") | E15: =IF(3<=Setup!$C$10,3,"") | F15: =IF(4<=Setup!$C$10,4,"") | G15: =IF(0<=Setup!$D$10,0,"") | H15: =IF(1<=Setup!$D$10,1,"") | I15: =IF(2<=Setup!$D$10,2,"") | J15: =IF(3<=Setup!$D$10,3,"") | K15: =IF(4<=Setup!$D$10,4,"") | L15: =IF(5<=Setup!$D$10,5,"") | M15: =IF(6<=Setup!$D$10,6,"")
A16: 5 | B16: =IF(0<=Setup!$C$11,0,"") | C16: =IF(1<=Setup!$C$11,1,"") | D16: =IF(2<=Setup!$C$11,2,"") | E16: =IF(3<=Setup!$C$11,3,"") | F16: =IF(4<=Setup!$C$11,4,"") | G16: =IF(0<=Setup!$D$11,0,"") | H16: =IF(1<=Setup!$D$11,1,"") | I16: =IF(2<=Setup!$D$11,2,"") | J16: =IF(3<=Setup!$D$11,3,"") | K16: =IF(4<=Setup!$D$11,4,"") | L16: =IF(5<=Setup!$D$11,5,"") | M16: =IF(6<=Setup!$D$11,6,"")
A17: TOTAL SCORE →
A19: =Setup!$B$3&" • Rubric: Problem Set "&Setup!$B$4
A20: Prob | B20: Final Answer | G20: Concept & Execution | N20: Score
A21: 1 | B21: =IF(0<=Setup!$C$7,0,"") | C21: =IF(1<=Setup!$C$7,1,"") | D21: =IF(2<=Setup!$C$7,2,"") | E21: =IF(3<=Setup!$C$7,3,"") | F21: =IF(4<=Setup!$C$7,4,"") | G21: =IF(0<=Setup!$D$7,0,"") | H21: =IF(1<=Setup!$D$7,1,"") | I21: =IF(2<=Setup!$D$7,2,"") | J21: =IF(3<=Setup!$D$7,3,"") | K21: =IF(4<=Setup!$D$7,4,"") | L21: =IF(5<=Setup!$D$7,5,"") | M21: =IF(6<=Setup!$D$7,6,"")
A22: 2 | B22: =IF(0<=Setup!$C$8,0,"") | C22: =IF(1<=Setup!$C$8,1,"") | D22: =IF(2<=Setup!$C$8,2,"") | E22: =IF(3<=Setup!$C$8,3,"") | F22: =IF(4<=Setup!$C$8,4,"") | G22: =IF(0<=Setup!$D$8,0,"") | H22: =IF(1<=Setup!$D$8,1,"") | I22: =IF(2<=Setup!$D$8,2,"") | J22: =IF(3<=Setup!$D$8,3,"") | K22: =IF(4<=Setup!$D$8,4,"") | L22: =IF(5<=Setup!$D$8,5,"") | M22: =IF(6<=Setup!$D$8,6,"")
A23: 3 | B23: =IF(0<=Setup!$C$9,0,"") | C23: =IF(1<=Setup!$C$9,1,"") | D23: =IF(2<=Setup!$C$9,2,"") | E23: =IF(3<=Setup!$C$9,3,"") | F23: =IF(4<=Setup!$C$9,4,"") | G23: =IF(0<=Setup!$D$9,0,"") | H23: =IF(1<=Setup!$D$9,1,"") | I23: =IF(2<=Setup!$D$9,2,"") | J23: =IF(3<=Setup!$D$9,3,"") | K23: =IF(4<=Setup!$D$9,4,"") | L23: =IF(5<=Setup!$D$9,5,"") | M23: =IF(6<=Setup!$D$9,6,"")
A24: 4 | B24: =IF(0<=Setup!$C$10,0,"") | C24: =IF(1<=Setup!$C$10,1,"") | D24: =IF(2<=Setup!$C$10,2,"") | E24: =IF(3<=Setup!$C$10,3,"") | F24: =IF(4<=Setup!$C$10,4,"") | G24: =IF(0<=Setup!$D$10,0,"") | H24: =IF(1<=Setup!$D$10,1,"") | I24: =IF(2<=Setup!$D$10,2,"") | J24: =IF(3<=Setup!$D$10,3,"") | K24: =IF(4<=Setup!$D$10,4,"") | L24: =IF(5<=Setup!$D$10,5,"") | M24: =IF(6<=Setup!$D$10,6,"")
A25: 5 | B25: =IF(0<=Setup!$C$11,0,"") | C25: =IF(1<=Setup!$C$11,1,"") | D25: =IF(2<=Setup!$C$11,2,"") | E25: =IF(3<=Setup!$C$11,3,"") | F25: =IF(4<=Setup!$C$11,4,"") | G25: =IF(0<=Setup!$D$11,0,"") | H25: =IF(1<=Setup!$D$11,1,"") | I25: =IF(2<=Setup!$D$11,2,"") | J25: =IF(3<=Setup!$D$11,3,"") | K25: =IF(4<=Setup!$D$11,4,"") | L25: =IF(5<=Setup!$D$11,5,"") | M25: =IF(6<=Setup!$D$11,6,"")
A26: TOTAL SCORE →
A28: =Setup!$B$3&" • Rubric: Problem Set "&Setup!$B$4
A29: Prob | B29: Final Answer | G29: Concept & Execution | N29: Score
A30: 1 | B30: =IF(0<=Setup!$C$7,0,"") | C30: =IF(1<=Setup!$C$7,1,"") | D30: =IF(2<=Setup!$C$7,2,"") | E30: =IF(3<=Setup!$C$7,3,"") | F30: =IF(4<=Setup!$C$7,4,"") | G30: =IF(0<=Setup!$D$7,0,"") | H30: =IF(1<=Setup!$D$7,1,"") | I30: =IF(2<=Setup!$D$7,2,"") | J30: =IF(3<=Setup!$D$7,3,"") | K30: =IF(4<=Setup!$D$7,4,"") | L30: =IF(5<=Setup!$D$7,5,"") | M30: =IF(6<=Setup!$D$7,6,"")
A31: 2 | B31: =IF(0<=Setup!$C$8,0,"") | C31: =IF(1<=Setup!$C$8,1,"") | D31: =IF(2<=Setup!$C$8,2,"") | E31: =IF(3<=Setup!$C$8,3,"") | F31: =IF(4<=Setup!$C$8,4,"") | G31: =IF(0<=Setup!$D$8,0,"") | H31: =IF(1<=Setup!$D$8,1,"") | I31: =IF(2<=Setup!$D$8,2,"") | J31: =IF(3<=Setup!$D$8,3,"") | K31: =IF(4<=Setup!$D$8,4,"") | L31: =IF(5<=Setup!$D$8,5,"") | M31: =IF(6<=Setup!$D$8,6,"")
A32: 3 | B32: =IF(0<=Setup!$C$9,0,"") | C32: =IF(1<=Setup!$C$9,1,"") | D32: =IF(2<=Setup!$C$9,2,"") | E32: =IF(3<=Setup!$C$9,3,"") | F32: =IF(4<=Setup!$C$9,4,"") | G32: =IF(0<=Setup!$D$9,0,"") | H32: =IF(1<=Setup!$D$9,1,"") | I32: =IF(2<=Setup!$D$9,2,"") | J32: =IF(3<=Setup!$D$9,3,"") | K32: =IF(4<=Setup!$D$9,4,"") | L32: =IF(5<=Setup!$D$9,5,"") | M32: =IF(6<=Setup!$D$9,6,"")
A33: 4 | B33: =IF(0<=Setup!$C$10,0,"") | C33: =IF(1<=Setup!$C$10,1,"") | D33: =IF(2<=Setup!$C$10,2,"") | E33: =IF(3<=Setup!$C$10,3,"") | F33: =IF(4<=Setup!$C$10,4,"") | G33: =IF(0<=Setup!$D$10,0,"") | H33: =IF(1<=Setup!$D$10,1,"") | I33: =IF(2<=Setup!$D$10,2,"") | J33: =IF(3<=Setup!$D$10,3,"") | K33: =IF(4<=Setup!$D$10,4,"") | L33: =IF(5<=Setup!$D$10,5,"") | M33: =IF(6<=Setup!$D$10,6,"")
A34: 5 | B34: =IF(0<=Setup!$C$11,0,"") | C34: =IF(1<=Setup!$C$11,1,"") | D34: =IF(2<=Setup!$C$11,2,"") | E34: =IF(3<=Setup!$C$11,3,"") | F34: =IF(4<=Setup!$C$11,4,"") | G34: =IF(0<=Setup!$D$11,0,"") | H34: =IF(1<=Setup!$D$11,1,"") | I34: =IF(2<=Setup!$D$11,2,"") | J34: =IF(3<=Setup!$D$11,3,"") | K34: =IF(4<=Setup!$D$11,4,"") | L34: =IF(5<=Setup!$D$11,5,"") | M34: =IF(6<=Setup!$D$11,6,"")
A35: TOTAL SCORE →
A37: =Setup!$B$3&" • Rubric: Problem Set "&Setup!$B$4
A38: Prob | B38: Final Answer | G38: Concept & Execution | N38: Score
A39: 1 | B39: =IF(0<=Setup!$C$7,0,"") | C39: =IF(1<=Setup!$C$7,1,"") | D39: =IF(2<=Setup!$C$7,2,"") | E39: =IF(3<=Setup!$C$7,3,"") | F39: =IF(4<=Setup!$C$7,4,"") | G39: =IF(0<=Setup!$D$7,0,"") | H39: =IF(1<=Setup!$D$7,1,"") | I39: =IF(2<=Setup!$D$7,2,"") | J39: =IF(3<=Setup!$D$7,3,"") | K39: =IF(4<=Setup!$D$7,4,"") | L39: =IF(5<=Setup!$D$7,5,"") | M39: =IF(6<=Setup!$D$7,6,"")
A40: 2 | B40: =IF(0<=Setup!$C$8,0,"") | C40: =IF(1<=Setup!$C$8,1,"") | D40: =IF(2<=Setup!$C$8,2,"") | E40: =IF(3<=Setup!$C$8,3,"") | F40: =IF(4<=Setup!$C$8,4,"") | G40: =IF(0<=Setup!$D$8,0,"") | H40: =IF(1<=Setup!$D$8,1,"") | I40: =IF(2<=Setup!$D$8,2,"") | J40: =IF(3<=Setup!$D$8,3,"") | K40: =IF(4<=Setup!$D$8,4,"") | L40: =IF(5<=Setup!$D$8,5,"") | M40: =IF(6<=Setup!$D$8,6,"")
A41: 3 | B41: =IF(0<=Setup!$C$9,0,"") | C41: =IF(1<=Setup!$C$9,1,"") | D41: =IF(2<=Setup!$C$9,2,"") | E41: =IF(3<=Setup!$C$9,3,"") | F41: =IF(4<=Setup!$C$9,4,"") | G41: =IF(0<=Setup!$D$9,0,"") | H41: =IF(1<=Setup!$D$9,1,"") | I41: =IF(2<=Setup!$D$9,2,"") | J41: =IF(3<=Setup!$D$9,3,"") | K41: =IF(4<=Setup!$D$9,4,"") | L41: =IF(5<=Setup!$D$9,5,"") | M41: =IF(6<=Setup!$D$9,6,"")
A42: 4 | B42: =IF(0<=Setup!$C$10,0,"") | C42: =IF(1<=Setup!$C$10,1,"") | D42: =IF(2<=Setup!$C$10,2,"") | E42: =IF(3<=Setup!$C$10,3,"") | F42: =IF(4<=Setup!$C$10,4,"") | G42: =IF(0<=Setup!$D$10,0,"") | H42: =IF(1<=Setup!$D$10,1,"") | I42: =IF(2<=Setup!$D$10,2,"") | J42: =IF(3<=Setup!$D$10,3,"") | K42: =IF(4<=Setup!$D$10,4,"") | L42: =IF(5<=Setup!$D$10,5,"") | M42: =IF(6<=Setup!$D$10,6,"")
A43: 5 | B43: =IF(0<=Setup!$C$11,0,"") | C43: =IF(1<=Setup!$C$11,1,"") | D43: =IF(2<=Setup!$C$11,2,"") | E43: =IF(3<=Setup!$C$11,3,"") | F43: =IF(4<=Setup!$C$11,4,"") | G43: =IF(0<=Setup!$D$11,0,"") | H43: =IF(1<=Setup!$D$11,1,"") | I43: =IF(2<=Setup!$D$11,2,"") | J43: =IF(3<=Setup!$D$11,3,"") | K43: =IF(4<=Setup!$D$11,4,"") | L43: =IF(5<=Setup!$D$11,5,"") | M43: =IF(6<=Setup!$D$11,6,"")
A44: TOTAL SCORE →
...

Sheet Rubric Guide
A1: GRADING RUBRIC — GUIDE
A2: Two dimensions per problem: Final Answer (the result) and Concept & Execution (the physics and the math). Single-unknown problems total 5 pts; multi-step / multi-unknown problems total 10 pts.
A4: What each dimension measures
A5: Final Answer — Did you land the correct result, properly expressed? Correct value(s), units, and significant figures. This is the ONLY place units and sig figs are judged.
A6: Concept & Execution — Do you understand the physics and can you carry it out? Right principle/equation (concept) + correct substitution, algebra, and method (execution) + clear, ordered, labeled work (communication). Graded on process, using Error-Carried-Forward.
A8: Grading rules (apply before scoring)
A9: 1. Score each column on its own descriptor; never penalize the same flaw twice. Units/sig-fig issues affect only Final Answer.
A10: 2. Error-Carried-Forward (ECF): judge each step against the student's own prior results, not the answer key.
A11: 3. Consistency (default): the two columns should tell the same story — strong process usually accompanies a correct answer.
A12: 4. ECF override: if the ONLY defect is a single arithmetic/transcription slip and every later step is correct under ECF, score Concept & Execution on process merit (it may reach the top band) even though the final answer is wrong.
A13: 5. Answer only / no work shown: score Final Answer on merit; Concept & Execution = 0.
A14: 6. Blank: 0 / 0.
A16: TYPE A — Single-unknown (Total 5)
A17: Final Answer (0–2) | B17: Description
A18: 2 | B18: Correct value, correct units, appropriate significant figures.
A19: 1 | B19: Correct value but units/sig figs wrong, OR a single arithmetic slip giving a near-correct value.
A20: 0 | B20: Incorrect, or blank.
A21: Concept & Execution (0–3) | B21: Description
A22: 3 | B22: Correct principle/equation; substitution and algebra correct; work clear and complete.
A23: 2 | B23: Correct principle; essentially right, with a minor execution slip or sparse-but-followable steps.
A24: 1 | B24: Relevant concept present, but undermined by a wrong equation or a substantive execution error.
A25: 0 | B25: Wrong concept, or no meaningful work.
A27: TYPE B — Multi-step / multi-unknown (Total 10)
A28: Final Answer (0–4) | B28: Description
A29: 4 | B29: Every required final value correct, with correct units.
A30: 3 | B30: All but one correct; the single miss is minor (units, sig figs, or one small slip).
A31: 2 | B31: Roughly half the values correct.
A32: 1 | B32: One value correct, or most contain significant errors.
A33: 0 | B33: No correct values, or blank.
A34: Concept & Execution (0–6) | B34: Description
A35: 6 | B35: Correct principle at EVERY step; all substitution, algebra, and units correct (ECF); logically ordered, labeled, easy to follow.
A36: 5 | B36: Correct principles and method throughout; at most one trivial slip or slightly sparse justification — physics fully sound.
A37: 4 | B37: Correct approach on the main steps, but ONE real execution error or one wrong/missing equation; work still followable.
A38: 3 | B38: Correct on some steps, but a wrong principle on a major step and/or several execution errors; reasoning has gaps.
A39: 2 | B39: Mostly incorrect method; more than a token of correct physics but hard to follow.
... A41: 0 | B41: No meaningful work, or blank.
